Workbook

Sheet Cover
B2: SLC MANAGEMENT
B3: Finance Monthly Close & Reporting System
B4: End-to-end pipeline simulation: Raw Data → Validation → Reporting
B6: ="Reporting Period: "&TEXT(Processed_Model!B2,"mmmm yyyy")&" • Prior: "&TEXT(Processed_Model!B3,"mmmm yyyy")&" • Built by Finance Data Operations" -> Reporting Period: September 2025 • Prior: August 2025 • Built by Finance Data Operations
B8: WHAT THIS IS
B9: A working simulation of the monthly close, validation, and reporting workflow that a Finance Data Analyst on SLC Management's Finance Data Analytics & Insights team would own. The workbook ingests three monthly source feeds — AUM, General Ledger, and fund-level Investments — runs them through a controls layer that surfaces tie-out breaks, variances, and data-quality issues, and presents the results on a leadership-ready dashboard. Every figure on the dashboard traces back through formulas to the raw tables; nothing is hardcoded.
B11: AT A GLANCE
B12: TOTAL AUM | D12: MoM Δ AUM | F12: NET INCOME | H12: OPEN EXCEPTIONS
B13: ="$"&TEXT(SUMIFS(tblAUM[AUM_CAD_Billions],tblAUM[Date],Processed_Model!B2),"#,##0.0")&"B" -> $428.9B | D13: =TEXT(IFERROR(SUMIFS(tblAUM[AUM_CAD_Billions],tblAUM[Date],Processed_Model!B2)/SUMIFS(tblAUM[AUM_CAD_Billions],tblAUM[Date],Processed_Model!B3)-1,0),"+0.00%;-0.00%") -> -7.13% | F13: ="$"&TEXT(SUMIFS(tblGL[Amount_CAD_Millions],tblGL[Date],Processed_Model!B2),"#,##0.0")&"M" -> $64.2M | H13: {=COUNTIF(Controls!G6:G14,"FAIL")+COUNTIFS(Controls!G18:G23,"FLAG")+COUNTIFS(Controls!G18:G23,"INVESTIGATE")+SUMPRODUCT(--ISNUMBER(SEARCH("FAIL",Controls!G27:G33)))} -> 10
B14: Reporting period total | D14: Current vs prior month | F14: GL revenue – expenses | H14: Surfaced by controls
B16: HOW IT WORKS — DATA PIPELINE
B17: 1 RAW DATA | D17: 2 PROCESSED MODEL | F17: 3 CONTROLS | H17: 4 REPORTING
B18: Three structured tables — tblAUM, tblGL, tblInvestments — append-only monthly feeds with source-file traceability. | D18: Parameter-driven SUMIFS rollups by month, segment, and asset class. One source of truth for all reporting. | F18: 9 tie-outs + 6 variance checks + 7 data-quality checks. PASS / FLAG / FAIL surfaced automatically. | H18: KPI dashboard, variance breakdown, and exception register. Everything traces back to raw via formulas.
B21: WHAT'S IN THE WORKBOOK
B22: Sheet | D22: Layer | F22: What it contains
B23: Cover (this sheet) | D23: Documentation | F23: Project overview, KPIs, pipeline, navigation
B24: README | D24: Documentation | F24: Runbook, controls framework, data dictionary, version log
B25: Dashboard | D25: Reporting | F25: KPI cards, AUM trend, segment mix, GL charts, exception summary
B26: Variance_Detail | D26: Reporting | F26: Segment × asset class drilldown — current vs prior month
B27: Controls | D27: Validation | F27: 9 tie-outs, 6 variance checks, 7 DQ checks, exception register
B28: Processed_Model | D28: Logic | F28: Parameters, monthly rollups, by-segment summaries (SUMIFS)
B29: Raw_AUM | D29: Source Data | F29: tblAUM — 24 months × 3 segments × 3 asset classes
B30: Raw_GL | D30: Source Data | F30: tblGL — 24 months × 3 segments × 8 accounts
B31: Raw_Investments | D31: Source Data | F31: tblInvestments — fund-level Market Value & Returns (Aug + Sep 2025)
B33: HOW TO USE THIS WORKBOOK | F33: DESIGN PRINCIPLES
B34: 1 | C34: Start at the Dashboard for the top-line view of AUM, revenue, profitability, and any open exceptions. | F34: • | G34: Automation-first — zero manual edits in the processed/reporting layers. Replace raw, recalc, done.
B35: 2 | C35: If exceptions are open, jump to Controls to see which checks failed and why; the Exception Register shows severity + owner. | F35: • | G35: Single source of truth — every figure traces back to one of three raw tables via SUMIFS.
B36: 3 | C36: For a detailed segment-level view, open Variance_Detail — current vs prior month broken down by asset class. | F36: • | G36: Structured Tables — formulas auto-expand as new rows append. No range maintenance needed.
B37: 4 | C37: To run a new month, append rows to the three Raw_* tables, update parameters on Processed_Model B2:B3, and recalculate. | F37: • | G37: Parameter-driven — change reporting period in two cells and the entire system shifts.
B38: 5 | C38: See the README for full runbook, controls framework, and data dictionary. | F38: • | G38: Controls baked in — every output validated by tie-outs, variance checks, and DQ rules.
B40: GO TO
B41: → DASHBOARD | D41: → CONTROLS | F41: → VARIANCE | H41: → README
B43: Built for SLC Management Finance Data Analyst & Insights | Version 1.0 | Owner: Finance Data Operations

Sheet README
A1: SLC MANAGEMENT — FINANCE MONTHLY CLOSE & REPORTING SYSTEM
A2: Runbook & Documentation | Owner: Finance Data Operations | Version 1.0
A3: → Dashboard | B3: → Controls | C3: → Variance | D3: → Model | E3: → Raw Data
A5: 1. PURPOSE
A6: This workbook simulates the end-to-end monthly close and reporting workflow for SLC Management's Finance Data Analytics & Insights team. It demonstrates an automation-first design with built-in tie-outs, data quality checks, variance analysis, and a leadership-ready dashboard. Replace the source data each month, recalc, and the entire system updates.
A8: 2. MONTHLY REFRESH PROCEDURE (one-click)
A9: Step 1 | B9: Receive monthly source files: AUM_<YYYY>_<MM>.csv, GL_<YYYY>_<MM>.csv, Investments_<YYYY>_<MM>.csv
A10: Step 2 | B10: Append new rows to the bottom of tblAUM (Raw_AUM), tblGL (Raw_GL), and tblInvestments (Raw_Investments). Tables auto-expand.
A11: Step 3 | B11: Update parameters on Processed_Model: B2 = current month (1st of month), B3 = prior month.
A12: Step 4 | B12: Press F9 (or Formulas → Calculate Now). All rollups, controls, and the dashboard refresh automatically.
A13: Step 5 | B13: Open Controls sheet — review any FAIL, FLAG, or INVESTIGATE statuses. Resolve or document each in the Exception Register.
A14: Step 6 | B14: Open Dashboard — confirm KPI band, trend, and segment mix. Sign off when Exception Summary shows ALL CLEAR or all open items have a documented owner.
A16: 3. SHEET DIRECTORY
A17: Sheet | B17: Layer | C17: Contents | D17: Edit? | E17: Refresh
A18: README | B18: Documentation | C18: Runbook, controls explanation, sheet map | D18: No | E18: —
A19: Raw_AUM | B19: Raw Data | C19: AUM Table — Date / Segment / Asset Class / AUM (tblAUM) | D19: Append rows monthly | E19: Auto
A20: Raw_GL | B20: Raw Data | C20: GL Summary — Date / Segment / Account / Type / Amount (tblGL) | D20: Append rows monthly | E20: Auto
A21: Raw_Investments | B21: Raw Data | C21: Fund-level Market Value & Returns (tblInvestments) | D21: Append rows monthly | E21: Auto
A22: Processed_Model | B22: Processed | C22: Parameters + AUM/GL/Investments rollups via SUMIFS | D22: No (formulas) | E22: Auto
A23: Controls | B23: Controls | C23: Tie-outs, variance checks, DQ, exception register | D23: No (formulas) | E23: Auto
A24: Variance_Detail | B24: Reporting | C24: Segment × Asset Class variance breakdown current vs prior | D24: No (formulas) | E24: Auto
A25: Dashboard | B25: Reporting | C25: KPI cards, trend chart, segment mix, exception summary | D25: No (formulas) | E25: Auto
A27: 4. CONTROLS FRAMEWORK
A28: # | B28: Layer | C28: Control | D28: What it catches | E28: Threshold
A29: A1-A6 | B29: Tie-outs | C29: AUM totals = Investments totals (overall + by segment) | D29: Duplicates / missing funds breaking the model | E29: ±$0.5B
A30: B1-B6 | B30: Variance | C30: Current vs Prior month — Total AUM, segment AUM, GL Revenue/Expenses | D30: Unexplained MoM swings | E30: ±5% (parameter B4)
A31: C1 | B31: DQ | C31: Missing AUM rows for current month | D31: Source file not received / partial submission | E31: 9 rows expected
A32: C2 | B32: DQ | C32: Missing GL rows for current month | D32: GL extract incomplete | E32: 24 rows expected
A33: C3 | B33: DQ | C33: Duplicate fund-period entries in Investments | D33: Double-loaded fund file | E33: 0 expected
A34: C4 | B34: DQ | C34: Outlier returns in current Investments | D34: Bad data / corporate action / genuine outlier | E34: |return| > 10%
A35: C5 | B35: DQ | C35: Negative AUM values | D35: Sign error or transformation bug | E35: 0 expected
A36: C6 | B36: DQ | C36: Blank AUM values | D36: Empty cells in source | E36: 0 expected
A37: C7 | B37: DQ | C37: Distinct segments in AUM | D37: Unexpected/misspelled segment | E37: exactly 3
A38: D | B38: Exceptions | C38: Auto-generated register of HIGH/MED issues | D38: Consolidated single-pane view for sign-off | E38: —
A40: 5. KNOWN SEEDED ISSUES (current period — for demo)
A41: Missing data | B41: Insurance segment AUM and Investments are intentionally absent for Sep-2025 to demonstrate missing-file detection. Tie-out 6 will FAIL; DQ check 1 will surface the gap; Exception register lists it as HIGH.
A42: Variance spike | B42: Wealth/Equities AUM is engineered to drop ~12% MoM in Sep-2025 (simulated market event). Variance check 3 flags FLAG; Variance_Detail row shows the segment × asset class drilldown.
A43: Duplicates | B43: Two fund rows (SLC Core Plus Fixed Income Fund, MFS Global Equity Sun Life Fund) appear twice in the Sep-2025 Investments table. DQ check 3 detects 2 duplicates; this is also why AUM↔Investments tie-out 1 fails.
A44: Outlier | B44: InfraRed Infrastructure Fund Sep-2025 return is set to +18.5% (above the 10% outlier threshold). DQ check 4 flags it for Investment Ops follow-up.
A46: 6. DESIGN PRINCIPLES
...

Sheet Dashboard
A1: SLC MANAGEMENT — FINANCE MONTHLY CLOSE DASHBOARD
A2: ="Reporting Period: "&TEXT(Processed_Model!B2,"mmmm yyyy")&" | Generated from automated pipeline" -> Reporting Period: September 2025 | Generated from automated pipeline
A4: TOTAL AUM (CAD $B) | C4: MoM Δ AUM | E4: REVENUE (CAD $M) | G4: NET INCOME (CAD $M)
A5: =SUMIFS(tblAUM[AUM_CAD_Billions],tblAUM[Date],Processed_Model!B2) -> 428.887 | C5: =IFERROR(SUMIFS(tblAUM[AUM_CAD_Billions],tblAUM[Date],Processed_Model!B2)/SUMIFS(tblAUM[AUM_CAD_Billions],tblAUM[Date],Processed_Model!B3)-1,"") -> -0.071281168 | E5: =SUMIFS(tblGL[Amount_CAD_Millions],tblGL[Date],Processed_Model!B2,tblGL[Type],"Revenue") -> 155.429 | G5: =SUMIFS(tblGL[Amount_CAD_Millions],tblGL[Date],Processed_Model!B2) -> 64.228
A7: ="Prior: $"&TEXT(SUMIFS(tblAUM[AUM_CAD_Billions],tblAUM[Date],Processed_Model!B3),"#,##0.0")&"B" -> Prior: $461.8B | C7: ="$"&TEXT(SUMIFS(tblAUM[AUM_CAD_Billions],tblAUM[Date],Processed_Model!B2)-SUMIFS(tblAUM[AUM_CAD_Billions],tblAUM[Date],Processed_Model!B3),"+#,##0.0;-#,##0.0")&"B change" -> $-32.9B change | E7: ="vs Prior: "&TEXT(IFERROR(SUMIFS(tblGL[Amount_CAD_Millions],tblGL[Date],Processed_Model!B2,tblGL[Type],"Revenue")/SUMIFS(tblGL[Amount_CAD_Millions],tblGL[Date],Processed_Model!B3,tblGL[Type],"Revenue")-1,""),"+0.0%;-0.0%") -> vs Prior: +4.2% | G7: ="Op Margin: "&TEXT(IFERROR(SUMIFS(tblGL[Amount_CAD_Millions],tblGL[Date],Processed_Model!B2)/SUMIFS(tblGL[Amount_CAD_Millions],tblGL[Date],Processed_Model!B2,tblGL[Type],"Revenue"),""),"0.0%") -> Op Margin: 41.3%
A9: AUM BY SEGMENT — Current Month | E9: EXCEPTION SUMMARY
A10: Segment | B10: Current ($B) | C10: Prior ($B) | D10: Δ % | E10: Category | F10: Count | H10: Status
A11: Asset Management | B11: =SUMIFS(tblAUM[AUM_CAD_Billions],tblAUM[Date],Processed_Model!$B$2,tblAUM[Segment],A11) -> 371.546 | C11: =SUMIFS(tblAUM[AUM_CAD_Billions],tblAUM[Date],Processed_Model!$B$3,tblAUM[Segment],A11) -> 370.091 | D11: =IFERROR(B11/C11-1,"") -> 0.0039314655 | E11: Tie-out Failures | F11: =COUNTIF(Controls!G6:G14,"FAIL") -> 4 | H11: =IF(F11=0,"✓ CLEAR","⚠ ATTENTION") -> ⚠ ATTENTION
A12: Wealth | B12: =SUMIFS(tblAUM[AUM_CAD_Billions],tblAUM[Date],Processed_Model!$B$2,tblAUM[Segment],A12) -> 57.341 | C12: =SUMIFS(tblAUM[AUM_CAD_Billions],tblAUM[Date],Processed_Model!$B$3,tblAUM[Segment],A12) -> 61.038 | D12: =IFERROR(B12/C12-1,"") -> -0.060568826 | E12: Variance Flags (>threshold) | F12: =COUNTIFS(Controls!G18:G23,"FLAG")+COUNTIFS(Controls!G18:G23,"INVESTIGATE") -> 3 | H12: =IF(F12=0,"✓ CLEAR","⚠ ATTENTION") -> ⚠ ATTENTION
A13: Insurance | B13: =SUMIFS(tblAUM[AUM_CAD_Billions],tblAUM[Date],Processed_Model!$B$2,tblAUM[Segment],A13) -> 0 | C13: =SUMIFS(tblAUM[AUM_CAD_Billions],tblAUM[Date],Processed_Model!$B$3,tblAUM[Segment],A13) -> 30.676 | D13: =IFERROR(B13/C13-1,"") -> -1 | E13: Data Quality Failures | F13: {=SUMPRODUCT(--ISNUMBER(SEARCH("FAIL",Controls!G27:G33)))} -> 3 | H13: =IF(F13=0,"✓ CLEAR","⚠ ATTENTION") -> ⚠ ATTENTION
A14: TOTAL | B14: =SUM(B11:B13) -> 428.887 | C14: =SUM(C11:C13) -> 461.805 | D14: =IFERROR(B14/C14-1,"") -> -0.071281168 | E14: Total Open Exceptions | F14: =SUM(F11:F13) -> 10 | H14: =IF(F14=0,"✓ ALL CLEAR",F14&" ITEM(S) OPEN") -> 10 ITEM(S) OPEN
A50: NAVIGATION
A51: → README | C51: → Controls Detail | E51: → Variance Detail | G51: → Processed Model

Sheet Raw_AUM
A1: Date | B1: Segment | C1: Asset_Class | D1: AUM_CAD_Billions | E1: Source_File
A2: 45200 | B2: Asset Management | C2: Fixed Income | D2: 216.244 | E2: AUM_2023_10.csv
A3: 45200 | B3: Asset Management | C3: Equities | D3: 28.133 | E3: AUM_2023_10.csv
A4: 45200 | B4: Asset Management | C4: Alternatives | D4: 95.654 | E4: AUM_2023_10.csv
A5: 45200 | B5: Wealth | C5: Fixed Income | D5: 18.073 | E5: AUM_2023_10.csv
A6: 45200 | B6: Wealth | C6: Equities | D6: 32.03 | E6: AUM_2023_10.csv
A7: 45200 | B7: Wealth | C7: Alternatives | D7: 6.02 | E7: AUM_2023_10.csv
A8: 45200 | B8: Insurance | C8: Fixed Income | D8: 22.032 | E8: AUM_2023_10.csv
A9: 45200 | B9: Insurance | C9: Equities | D9: 3.973 | E9: AUM_2023_10.csv
A10: 45200 | B10: Insurance | C10: Alternatives | D10: 2.006 | E10: AUM_2023_10.csv
A11: 45231 | B11: Asset Management | C11: Fixed Income | D11: 216.769 | E11: AUM_2023_11.csv
A12: 45231 | B12: Asset Management | C12: Equities | D12: 28.201 | E12: AUM_2023_11.csv
A13: 45231 | B13: Asset Management | C13: Alternatives | D13: 95.125 | E13: AUM_2023_11.csv
... A214: 45901 | B214: Wealth | C214: Alternatives | D214: 6.598 | E214: AUM_2025_09.csv

Sheet Raw_GL
A1: Date | B1: Segment | C1: Account_Code | D1: Account_Name | E1: Type | F1: Amount_CAD_Millions | G1: Source_File
A2: 45200 | B2: Asset Management | C2: 4000 | D2: Management Fees | E2: Revenue | F2: 97.957 | G2: GL_2023_10.csv
A3: 45200 | B3: Asset Management | C3: 4100 | D3: Performance Fees | E3: Revenue | F3: 12.403 | G3: GL_2023_10.csv
A4: 45200 | B4: Asset Management | C4: 4200 | D4: Other Investment Income | E4: Revenue | F4: 4.828 | G4: GL_2023_10.csv
A5: 45200 | B5: Asset Management | C5: 5000 | D5: Compensation & Benefits | E5: Expense | F5: -37.678 | G5: GL_2023_10.csv
A6: 45200 | B6: Asset Management | C6: 5100 | D6: Sub-Advisory Fees | E6: Expense | F6: -8.26 | G6: GL_2023_10.csv
A7: 45200 | B7: Asset Management | C7: 5200 | D7: Technology & Data | E7: Expense | F7: -5.827 | G7: GL_2023_10.csv
A8: 45200 | B8: Asset Management | C8: 5300 | D8: Professional Fees | E8: Expense | F8: -2.969 | G8: GL_2023_10.csv
A9: 45200 | B9: Asset Management | C9: 5400 | D9: Occupancy & Other | E9: Expense | F9: -4 | G9: GL_2023_10.csv
A10: 45200 | B10: Wealth | C10: 4000 | D10: Management Fees | E10: Revenue | F10: 18.175 | G10: GL_2023_10.csv
A11: 45200 | B11: Wealth | C11: 4100 | D11: Performance Fees | E11: Revenue | F11: 1.957 | G11: GL_2023_10.csv
A12: 45200 | B12: Wealth | C12: 4200 | D12: Other Investment Income | E12: Revenue | F12: 1.454 | G12: GL_2023_10.csv
A13: 45200 | B13: Wealth | C13: 5000 | D13: Compensation & Benefits | E13: Expense | F13: -9.314 | G13: GL_2023_10.csv
... A577: 45901 | B577: Insurance | C577: 5400 | D577: Occupancy & Other | E577: Expense | F577: -0.768 | G577: GL_2025_09.csv

Sheet Raw_Investments
A1: Date | B1: Fund_Name | C1: Segment | D1: Asset_Class | E1: Market_Value_CAD_Billions | F1: Return_Pct | G1: Source_File
A2: 45870 | B2: SLC Core Plus Fixed Income Fund | C2: Asset Management | D2: Fixed Income | E2: 62.073 | F2: 0.08 | G2: Investments_2025_08.csv
A3: 45870 | B3: SLC Long Duration Bond Fund | C3: Asset Management | D3: Fixed Income | E3: 48.011 | F3: -0.45 | G3: Investments_2025_08.csv
A4: 45870 | B4: SLC Investment Grade Credit Fund | C4: Asset Management | D4: Fixed Income | E4: 41.798 | F4: -0.09 | G4: Investments_2025_08.csv
A5: 45870 | B5: SLC Liability Driven Investment Fund | C5: Asset Management | D5: Fixed Income | E5: 38.695 | F5: -0.24 | G5: Investments_2025_08.csv
A6: 45870 | B6: SLC Short Duration Income Fund | C6: Asset Management | D6: Fixed Income | E6: 24.594 | F6: 0.43 | G6: Investments_2025_08.csv
A7: 45870 | B7: SLC Global Equity Fund | C7: Asset Management | D7: Equities | E7: 14.335 | F7: -0.89 | G7: Investments_2025_08.csv
A8: 45870 | B8: SLC Canadian Equity Fund | C8: Asset Management | D8: Equities | E8: 8.791 | F8: -0.67 | G8: Investments_2025_08.csv
A9: 45870 | B9: SLC Emerging Markets Equity Fund | C9: Asset Management | D9: Equities | E9: 5.038 | F9: -0.67 | G9: Investments_2025_08.csv
A10: 45870 | B10: BGO Core Plus Real Estate Fund | C10: Asset Management | D10: Alternatives | E10: 35.36 | F10: 1.31 | G10: Investments_2025_08.csv
A11: 45870 | B11: Crescent Direct Lending Fund | C11: Asset Management | D11: Alternatives | E11: 28.145 | F11: 1.33 | G11: Investments_2025_08.csv
A12: 45870 | B12: InfraRed Infrastructure Fund | C12: Asset Management | D12: Alternatives | E12: 22.648 | F12: 1.1 | G12: Investments_2025_08.csv
A13: 45870 | B13: SLC Private Credit Fund | C13: Asset Management | D13: Alternatives | E13: 9.45 | F13: 1.24 | G13: Investments_2025_08.csv
... A40: 45901 | B40: MFS Global Equity Sun Life Fund | C40: Wealth | D40: Equities | E40: 16.194 | F40: -8.5 | G40: Investments_2025_09.csv

Sheet Processed_Model
A1: PARAMETERS | D1: AUM MONTHLY ROLLUP (CAD $B) | K1: GL MONTHLY ROLLUP (CAD $M) | Q1: INVESTMENTS ROLLUP — CURRENT MONTH (CAD $B) | V1: GL BY SEGMENT — Current Month (CAD $M) | AB1: GL BY SEGMENT — Prior Month (CAD $M) | AH1: AUM Mix Chart Helper (Cover/Dashboard)
A2: Current Reporting Month | B2: =DATE(2025,9,1) -> 45901 | D2: Month | E2: Asset Management | F2: Wealth | G2: Insurance | H2: Total AUM | I2: MoM Change % | K2: Month | L2: Revenue | M2: Expenses | N2: Net Income | O2: Operating Margin % | Q2: Segment | R2: Asset Class | S2: Current MV ($B) | T2: Prior MV ($B) | V2: Segment | W2: Revenue | X2: Expenses | Y2: Net Income | Z2: Margin % | AB2: Segment | AC2: Revenue | AD2: Expenses | AE2: Net Income | AF2: Margin % | AH2: Segment | AI2: Current ($B)
A3: Prior Reporting Month | B3: =DATE(2025,8,1) -> 45870 | D3: =DATE(2023,10,1) -> 45200 | E3: =SUMIFS(tblAUM[AUM_CAD_Billions],tblAUM[Date],D3,tblAUM[Segment],"Asset Management") -> 340.031 | F3: =SUMIFS(tblAUM[AUM_CAD_Billions],tblAUM[Date],D3,tblAUM[Segment],"Wealth") -> 56.123 | G3: =SUMIFS(tblAUM[AUM_CAD_Billions],tblAUM[Date],D3,tblAUM[Segment],"Insurance") -> 28.011 | H3: =SUM(E3:G3) -> 424.165 | K3: =D3 -> 45200 | L3: =SUMIFS(tblGL[Amount_CAD_Millions],tblGL[Date],K3,tblGL[Type],"Revenue") -> 145.816 | M3: =-SUMIFS(tblGL[Amount_CAD_Millions],tblGL[Date],K3,tblGL[Type],"Expense") -> 83.564 | N3: =L3-M3 -> 62.252 | O3: =IFERROR(N3/L3,"") -> 0.4269216 | Q3: Asset Management | R3: Fixed Income | S3: =SUMIFS(tblInvestments[Market_Value_CAD_Billions],tblInvestments[Date],$B$2,tblInvestments[Segment],Q3,tblInvestments[Asset_Class],R3) -> 279.835 | T3: =SUMIFS(tblInvestments[Market_Value_CAD_Billions],tblInvestments[Date],$B$3,tblInvestments[Segment],Q3,tblInvestments[Asset_Class],R3) -> 215.171 | V3: Asset Management | W3: =SUMIFS(tblGL[Amount_CAD_Millions],tblGL[Date],$B$2,tblGL[Segment],V3,tblGL[Type],"Revenue") -> 123 | X3: =-SUMIFS(tblGL[Amount_CAD_Millions],tblGL[Date],$B$2,tblGL[Segment],V3,tblGL[Type],"Expense") -> 64.731 | Y3: =W3-X3 -> 58.269 | Z3: =IFERROR(Y3/W3,"") -> 0.47373171 | AB3: Asset Management | AC3: =SUMIFS(tblGL[Amount_CAD_Millions],tblGL[Date],$B$3,tblGL[Segment],AB3,tblGL[Type],"Revenue") -> 115.98 | AD3: =-SUMIFS(tblGL[Amount_CAD_Millions],tblGL[Date],$B$3,tblGL[Segment],AB3,tblGL[Type],"Expense") -> 64.09 | AE3: =AC3-AD3 -> 51.89 | AF3: =IFERROR(AE3/AC3,"") -> 0.44740472 | AH3: =Dashboard!A11 -> Asset Management | AI3: =Dashboard!B11 -> 371.546
A4: Variance Threshold (%) | B4: 0.05 | D4: =DATE(2023,11,1) -> 45231 | E4: =SUMIFS(tblAUM[AUM_CAD_Billions],tblAUM[Date],D4,tblAUM[Segment],"Asset Management") -> 340.095 | F4: =SUMIFS(tblAUM[AUM_CAD_Billions],tblAUM[Date],D4,tblAUM[Segment],"Wealth") -> 56.55 | G4: =SUMIFS(tblAUM[AUM_CAD_Billions],tblAUM[Date],D4,tblAUM[Segment],"Insurance") -> 28.212 | H4: =SUM(E4:G4) -> 424.857 | I4: =IFERROR(H4/H3-1,"") -> 0.0016314406 | K4: =D4 -> 45231 | L4: =SUMIFS(tblGL[Amount_CAD_Millions],tblGL[Date],K4,tblGL[Type],"Revenue") -> 142.103 | M4: =-SUMIFS(tblGL[Amount_CAD_Millions],tblGL[Date],K4,tblGL[Type],"Expense") -> 83.484 | N4: =L4-M4 -> 58.619 | O4: =IFERROR(N4/L4,"") -> 0.41251064 | Q4: Asset Management | R4: Equities | S4: =SUMIFS(tblInvestments[Market_Value_CAD_Billions],tblInvestments[Date],$B$2,tblInvestments[Segment],Q4,tblInvestments[Asset_Class],R4) -> 28.091 | T4: =SUMIFS(tblInvestments[Market_Value_CAD_Billions],tblInvestments[Date],$B$3,tblInvestments[Segment],Q4,tblInvestments[Asset_Class],R4) -> 28.164 | V4: Wealth | W4: =SUMIFS(tblGL[Amount_CAD_Millions],tblGL[Date],$B$2,tblGL[Segment],V4,tblGL[Type],"Revenue") -> 22.403 | X4: =-SUMIFS(tblGL[Amount_CAD_Millions],tblGL[Date],$B$2,tblGL[Segment],V4,tblGL[Type],"Expense") -> 19.086 | Y4: =W4-X4 -> 3.317 | Z4: =IFERROR(Y4/W4,"") -> 0.14806053 | AB4: Wealth | AC4: =SUMIFS(tblGL[Amount_CAD_Millions],tblGL[Date],$B$3,tblGL[Segment],AB4,tblGL[Type],"Revenue") -> 23.476 | AD4: =-SUMIFS(tblGL[Amount_CAD_Millions],tblGL[Date],$B$3,tblGL[Segment],AB4,tblGL[Type],"Expense") -> 18.617 | AE4: =AC4-AD4 -> 4.859 | AF4: =IFERROR(AE4/AC4,"") -> 0.20697734 | AH4: =Dashboard!A12 -> Wealth | AI4: =Dashboard!B12 -> 57.341
A5: Outlier Return Threshold (%) | B5: 10 | D5: =DATE(2023,12,1) -> 45261 | E5: =SUMIFS(tblAUM[AUM_CAD_Billions],tblAUM[Date],D5,tblAUM[Segment],"Asset Management") -> 340.87 | F5: =SUMIFS(tblAUM[AUM_CAD_Billions],tblAUM[Date],D5,tblAUM[Segment],"Wealth") -> 56.342 | G5: =SUMIFS(tblAUM[AUM_CAD_Billions],tblAUM[Date],D5,tblAUM[Segment],"Insurance") -> 28.254 | H5: =SUM(E5:G5) -> 425.466 | I5: =IFERROR(H5/H4-1,"") -> 0.0014334235 | K5: =D5 -> 45261 | L5: =SUMIFS(tblGL[Amount_CAD_Millions],tblGL[Date],K5,tblGL[Type],"Revenue") -> 144.998 | M5: =-SUMIFS(tblGL[Amount_CAD_Millions],tblGL[Date],K5,tblGL[Type],"Expense") -> 85.785 | N5: =L5-M5 -> 59.213 | O5: =IFERROR(N5/L5,"") -> 0.40837115 | Q5: Asset Management | R5: Alternatives | S5: =SUMIFS(tblInvestments[Market_Value_CAD_Billions],tblInvestments[Date],$B$2,tblInvestments[Segment],Q5,tblInvestments[Asset_Class],R5) -> 96.075 | T5: =SUMIFS(tblInvestments[Market_Value_CAD_Billions],tblInvestments[Date],$B$3,tblInvestments[Segment],Q5,tblInvestments[Asset_Class],R5) -> 95.603 | V5: Insurance | W5: =SUMIFS(tblGL[Amount_CAD_Millions],tblGL[Date],$B$2,tblGL[Segment],V5,tblGL[Type],"Revenue") -> 10.026 | X5: =-SUMIFS(tblGL[Amount_CAD_Millions],tblGL[Date],$B$2,tblGL[Segment],V5,tblGL[Type],"Expense") -> 7.384 | Y5: =W5-X5 -> 2.642 | Z5: =IFERROR(Y5/W5,"") -> 0.26351486 | AB5: Insurance | AC5: =SUMIFS(tblGL[Amount_CAD_Millions],tblGL[Date],$B$3,tblGL[Segment],AB5,tblGL[Type],"Revenue") -> 9.712 | AD5: =-SUMIFS(tblGL[Amount_CAD_Millions],tblGL[Date],$B$3,tblGL[Segment],AB5,tblGL[Type],"Expense") -> 7.576 | AE5: =AC5-AD5 -> 2.136 | AF5: =IFERROR(AE5/AC5,"") -> 0.2199341 | AH5: =IF(Dashboard!B13=0,Dashboard!A13&" (no data)",Dashboard!A13) -> Insurance (no data) | AI5: =Dashboard!B13 -> 0
A6: Currency | B6: CAD Billions | D6: =DATE(2024,1,1) -> 45292 | E6: =SUMIFS(tblAUM[AUM_CAD_Billions],tblAUM[Date],D6,tblAUM[Segment],"Asset Management") -> 343.224 | F6: =SUMIFS(tblAUM[AUM_CAD_Billions],tblAUM[Date],D6,tblAUM[Segment],"Wealth") -> 56.766 | G6: =SUMIFS(tblAUM[AUM_CAD_Billions],tblAUM[Date],D6,tblAUM[Segment],"Insurance") -> 28.243 | H6: =SUM(E6:G6) -> 428.233 | I6: =IFERROR(H6/H5-1,"") -> 0.0065034574 | K6: =D6 -> 45292 | L6: =SUMIFS(tblGL[Amount_CAD_Millions],tblGL[Date],K6,tblGL[Type],"Revenue") -> 141.241 | M6: =-SUMIFS(tblGL[Amount_CAD_Millions],tblGL[Date],K6,tblGL[Type],"Expense") -> 85.383 | N6: =L6-M6 -> 55.858 | O6: =IFERROR(N6/L6,"") -> 0.39548007 | Q6: Wealth | R6: Fixed Income | S6: =SUMIFS(tblInvestments[Market_Value_CAD_Billions],tblInvestments[Date],$B$2,tblInvestments[Segment],Q6,tblInvestments[Asset_Class],R6) -> 18.324 | T6: =SUMIFS(tblInvestments[Market_Value_CAD_Billions],tblInvestments[Date],$B$3,tblInvestments[Segment],Q6,tblInvestments[Asset_Class],R6) -> 18.217 | V6: TOTAL | W6: =SUM(W3:W5) -> 155.429 | X6: =SUM(X3:X5) -> 91.201 | Y6: =W6-X6 -> 64.228 | Z6: =IFERROR(Y6/W6,"") -> 0.41323048 | AB6: TOTAL | AC6: =SUM(AC3:AC5) -> 149.168 | AD6: =SUM(AD3:AD5) -> 90.283 | AE6: =AC6-AD6 -> 58.885 | AF6: =IFERROR(AE6/AC6,"") -> 0.39475625
D7: =DATE(2024,2,1) -> 45323 | E7: =SUMIFS(tblAUM[AUM_CAD_Billions],tblAUM[Date],D7,tblAUM[Segment],"Asset Management") -> 342.719 | F7: =SUMIFS(tblAUM[AUM_CAD_Billions],tblAUM[Date],D7,tblAUM[Segment],"Wealth") -> 56.978 | G7: =SUMIFS(tblAUM[AUM_CAD_Billions],tblAUM[Date],D7,tblAUM[Segment],"Insurance") -> 28.525 | H7: =SUM(E7:G7) -> 428.222 | I7: =IFERROR(H7/H6-1,"") -> -2.5686951e-05 | K7: =D7 -> 45323 | L7: =SUMIFS(tblGL[Amount_CAD_Millions],tblGL[Date],K7,tblGL[Type],"Revenue") -> 145.766 | M7: =-SUMIFS(tblGL[Amount_CAD_Millions],tblGL[Date],K7,tblGL[Type],"Expense") -> 82.443 | N7: =L7-M7 -> 63.323 | O7: =IFERROR(N7/L7,"") -> 0.43441543 | Q7: Wealth | R7: Equities | S7: =SUMIFS(tblInvestments[Market_Value_CAD_Billions],tblInvestments[Date],$B$2,tblInvestments[Segment],Q7,tblInvestments[Asset_Class],R7) -> 44.516 | T7: =SUMIFS(tblInvestments[Market_Value_CAD_Billions],tblInvestments[Date],$B$3,tblInvestments[Segment],Q7,tblInvestments[Asset_Class],R7) -> 32.363
D8: =DATE(2024,3,1) -> 45352 | E8: =SUMIFS(tblAUM[AUM_CAD_Billions],tblAUM[Date],D8,tblAUM[Segment],"Asset Management") -> 344.497 | F8: =SUMIFS(tblAUM[AUM_CAD_Billions],tblAUM[Date],D8,tblAUM[Segment],"Wealth") -> 57.278 | G8: =SUMIFS(tblAUM[AUM_CAD_Billions],tblAUM[Date],D8,tblAUM[Segment],"Insurance") -> 28.512 | H8: =SUM(E8:G8) -> 430.287 | I8: =IFERROR(H8/H7-1,"") -> 0.0048222651 | K8: =D8 -> 45352 | L8: =SUMIFS(tblGL[Amount_CAD_Millions],tblGL[Date],K8,tblGL[Type],"Revenue") -> 142.957 | M8: =-SUMIFS(tblGL[Amount_CAD_Millions],tblGL[Date],K8,tblGL[Type],"Expense") -> 84.867 | N8: =L8-M8 -> 58.09 | O8: =IFERROR(N8/L8,"") -> 0.40634596 | Q8: Wealth | R8: Alternatives | S8: =SUMIFS(tblInvestments[Market_Value_CAD_Billions],tblInvestments[Date],$B$2,tblInvestments[Segment],Q8,tblInvestments[Asset_Class],R8) -> 6.005 | T8: =SUMIFS(tblInvestments[Market_Value_CAD_Billions],tblInvestments[Date],$B$3,tblInvestments[Segment],Q8,tblInvestments[Asset_Class],R8) -> 6.022
D9: =DATE(2024,4,1) -> 45383 | E9: =SUMIFS(tblAUM[AUM_CAD_Billions],tblAUM[Date],D9,tblAUM[Segment],"Asset Management") -> 347.444 | F9: =SUMIFS(tblAUM[AUM_CAD_Billions],tblAUM[Date],D9,tblAUM[Segment],"Wealth") -> 57.425 | G9: =SUMIFS(tblAUM[AUM_CAD_Billions],tblAUM[Date],D9,tblAUM[Segment],"Insurance") -> 28.733 | H9: =SUM(E9:G9) -> 433.602 | I9: =IFERROR(H9/H8-1,"") -> 0.0077041602 | K9: =D9 -> 45383 | L9: =SUMIFS(tblGL[Amount_CAD_Millions],tblGL[Date],K9,tblGL[Type],"Revenue") -> 148.925 | M9: =-SUMIFS(tblGL[Amount_CAD_Millions],tblGL[Date],K9,tblGL[Type],"Expense") -> 87.035 | N9: =L9-M9 -> 61.89 | O9: =IFERROR(N9/L9,"") -> 0.41557831 | Q9: Insurance | R9: Fixed Income | S9: =SUMIFS(tblInvestments[Market_Value_CAD_Billions],tblInvestments[Date],$B$2,tblInvestments[Segment],Q9,tblInvestments[Asset_Class],R9) -> 0 | T9: =SUMIFS(tblInvestments[Market_Value_CAD_Billions],tblInvestments[Date],$B$3,tblInvestments[Segment],Q9,tblInvestments[Asset_Class],R9) -> 21.934
D10: =DATE(2024,5,1) -> 45413 | E10: =SUMIFS(tblAUM[AUM_CAD_Billions],tblAUM[Date],D10,tblAUM[Segment],"Asset Management") -> 347.232 | F10: =SUMIFS(tblAUM[AUM_CAD_Billions],tblAUM[Date],D10,tblAUM[Segment],"Wealth") -> 57.631 | G10: =SUMIFS(tblAUM[AUM_CAD_Billions],tblAUM[Date],D10,tblAUM[Segment],"Insurance") -> 28.747 | H10: =SUM(E10:G10) -> 433.61 | I10: =IFERROR(H10/H9-1,"") -> 1.8450099e-05 | K10: =D10 -> 45413 | L10: =SUMIFS(tblGL[Amount_CAD_Millions],tblGL[Date],K10,tblGL[Type],"Revenue") -> 148.739 | M10: =-SUMIFS(tblGL[Amount_CAD_Millions],tblGL[Date],K10,tblGL[Type],"Expense") -> 85.026 | N10: =L10-M10 -> 63.713 | O10: =IFERROR(N10/L10,"") -> 0.42835437 | Q10: Insurance | R10: Equities | S10: =SUMIFS(tblInvestments[Market_Value_CAD_Billions],tblInvestments[Date],$B$2,tblInvestments[Segment],Q10,tblInvestments[Asset_Class],R10) -> 0 | T10: =SUMIFS(tblInvestments[Market_Value_CAD_Billions],tblInvestments[Date],$B$3,tblInvestments[Segment],Q10,tblInvestments[Asset_Class],R10) -> 4.034
D11: =DATE(2024,6,1) -> 45444 | E11: =SUMIFS(tblAUM[AUM_CAD_Billions],tblAUM[Date],D11,tblAUM[Segment],"Asset Management") -> 348.459 | F11: =SUMIFS(tblAUM[AUM_CAD_Billions],tblAUM[Date],D11,tblAUM[Segment],"Wealth") -> 57.712 | G11: =SUMIFS(tblAUM[AUM_CAD_Billions],tblAUM[Date],D11,tblAUM[Segment],"Insurance") -> 28.875 | H11: =SUM(E11:G11) -> 435.046 | I11: =IFERROR(H11/H10-1,"") -> 0.0033117317 | K11: =D11 -> 45444 | L11: =SUMIFS(tblGL[Amount_CAD_Millions],tblGL[Date],K11,tblGL[Type],"Revenue") -> 145.532 | M11: =-SUMIFS(tblGL[Amount_CAD_Millions],tblGL[Date],K11,tblGL[Type],"Expense") -> 84.188 | N11: =L11-M11 -> 61.344 | O11: =IFERROR(N11/L11,"") -> 0.42151554 | Q11: Insurance | R11: Alternatives | S11: =SUMIFS(tblInvestments[Market_Value_CAD_Billions],tblInvestments[Date],$B$2,tblInvestments[Segment],Q11,tblInvestments[Asset_Class],R11) -> 0 | T11: =SUMIFS(tblInvestments[Market_Value_CAD_Billions],tblInvestments[Date],$B$3,tblInvestments[Segment],Q11,tblInvestments[Asset_Class],R11) -> 1.991
D12: =DATE(2024,7,1) -> 45474 | E12: =SUMIFS(tblAUM[AUM_CAD_Billions],tblAUM[Date],D12,tblAUM[Segment],"Asset Management") -> 349.115 | F12: =SUMIFS(tblAUM[AUM_CAD_Billions],tblAUM[Date],D12,tblAUM[Segment],"Wealth") -> 58.007 | G12: =SUMIFS(tblAUM[AUM_CAD_Billions],tblAUM[Date],D12,tblAUM[Segment],"Insurance") -> 29.041 | H12: =SUM(E12:G12) -> 436.163 | I12: =IFERROR(H12/H11-1,"") -> 0.0025675446 | K12: =D12 -> 45474 | L12: =SUMIFS(tblGL[Amount_CAD_Millions],tblGL[Date],K12,tblGL[Type],"Revenue") -> 145.343 | M12: =-SUMIFS(tblGL[Amount_CAD_Millions],tblGL[Date],K12,tblGL[Type],"Expense") -> 86.697 | N12: =L12-M12 -> 58.646 | O12: =IFERROR(N12/L12,"") -> 0.40350068 | Q12: TOTAL | S12: =SUM(S3:S11) -> 472.846 | T12: =SUM(T3:T11) -> 423.499
D13: =DATE(2024,8,1) -> 45505 | E13: =SUMIFS(tblAUM[AUM_CAD_Billions],tblAUM[Date],D13,tblAUM[Segment],"Asset Management") -> 352.383 | F13: =SUMIFS(tblAUM[AUM_CAD_Billions],tblAUM[Date],D13,tblAUM[Segment],"Wealth") -> 58.238 | G13: =SUMIFS(tblAUM[AUM_CAD_Billions],tblAUM[Date],D13,tblAUM[Segment],"Insurance") -> 28.981 | H13: =SUM(E13:G13) -> 439.602 | I13: =IFERROR(H13/H12-1,"") -> 0.007884667 | K13: =D13 -> 45505 | L13: =SUMIFS(tblGL[Amount_CAD_Millions],tblGL[Date],K13,tblGL[Type],"Revenue") -> 147.938 | M13: =-SUMIFS(tblGL[Amount_CAD_Millions],tblGL[Date],K13,tblGL[Type],"Expense") -> 85.33 | N13: =L13-M13 -> 62.608 | O13: =IFERROR(N13/L13,"") -> 0.42320432
D14: =DATE(2024,9,1) -> 45536 | E14: =SUMIFS(tblAUM[AUM_CAD_Billions],tblAUM[Date],D14,tblAUM[Segment],"Asset Management") -> 354.373 | F14: =SUMIFS(tblAUM[AUM_CAD_Billions],tblAUM[Date],D14,tblAUM[Segment],"Wealth") -> 58.812 | G14: =SUMIFS(tblAUM[AUM_CAD_Billions],tblAUM[Date],D14,tblAUM[Segment],"Insurance") -> 29.271 | H14: =SUM(E14:G14) -> 442.456 | I14: =IFERROR(H14/H13-1,"") -> 0.0064922362 | K14: =D14 -> 45536 | L14: =SUMIFS(tblGL[Amount_CAD_Millions],tblGL[Date],K14,tblGL[Type],"Revenue") -> 147.514 | M14: =-SUMIFS(tblGL[Amount_CAD_Millions],tblGL[Date],K14,tblGL[Type],"Expense") -> 85.638 | N14: =L14-M14 -> 61.876 | O14: =IFERROR(N14/L14,"") -> 0.41945849
D15: =DATE(2024,10,1) -> 45566 | E15: =SUMIFS(tblAUM[AUM_CAD_Billions],tblAUM[Date],D15,tblAUM[Segment],"Asset Management") -> 354.458 | F15: =SUMIFS(tblAUM[AUM_CAD_Billions],tblAUM[Date],D15,tblAUM[Segment],"Wealth") -> 58.885 | G15: =SUMIFS(tblAUM[AUM_CAD_Billions],tblAUM[Date],D15,tblAUM[Segment],"Insurance") -> 29.49 | H15: =SUM(E15:G15) -> 442.833 | I15: =IFERROR(H15/H14-1,"") -> 0.00085206213 | K15: =D15 -> 45566 | L15: =SUMIFS(tblGL[Amount_CAD_Millions],tblGL[Date],K15,tblGL[Type],"Revenue") -> 147.36 | M15: =-SUMIFS(tblGL[Amount_CAD_Millions],tblGL[Date],K15,tblGL[Type],"Expense") -> 85.077 | N15: =L15-M15 -> 62.283 | O15: =IFERROR(N15/L15,"") -> 0.42265879
D16: =DATE(2024,11,1) -> 45597 | E16: =SUMIFS(tblAUM[AUM_CAD_Billions],tblAUM[Date],D16,tblAUM[Segment],"Asset Management") -> 355.85 | F16: =SUMIFS(tblAUM[AUM_CAD_Billions],tblAUM[Date],D16,tblAUM[Segment],"Wealth") -> 59.048 | G16: =SUMIFS(tblAUM[AUM_CAD_Billions],tblAUM[Date],D16,tblAUM[Segment],"Insurance") -> 29.402 | H16: =SUM(E16:G16) -> 444.3 | I16: =IFERROR(H16/H15-1,"") -> 0.0033127612 | K16: =D16 -> 45597 | L16: =SUMIFS(tblGL[Amount_CAD_Millions],tblGL[Date],K16,tblGL[Type],"Revenue") -> 151.882 | M16: =-SUMIFS(tblGL[Amount_CAD_Millions],tblGL[Date],K16,tblGL[Type],"Expense") -> 88.658 | N16: =L16-M16 -> 63.224 | O16: =IFERROR(N16/L16,"") -> 0.41627053
D17: =DATE(2024,12,1) -> 45627 | E17: =SUMIFS(tblAUM[AUM_CAD_Billions],tblAUM[Date],D17,tblAUM[Segment],"Asset Management") -> 357.556 | F17: =SUMIFS(tblAUM[AUM_CAD_Billions],tblAUM[Date],D17,tblAUM[Segment],"Wealth") -> 59.051 | G17: =SUMIFS(tblAUM[AUM_CAD_Billions],tblAUM[Date],D17,tblAUM[Segment],"Insurance") -> 29.557 | H17: =SUM(E17:G17) -> 446.164 | I17: =IFERROR(H17/H16-1,"") -> 0.0041953635 | K17: =D17 -> 45627 | L17: =SUMIFS(tblGL[Amount_CAD_Millions],tblGL[Date],K17,tblGL[Type],"Revenue") -> 143.99 | M17: =-SUMIFS(tblGL[Amount_CAD_Millions],tblGL[Date],K17,tblGL[Type],"Expense") -> 85.982 | N17: =L17-M17 -> 58.008 | O17: =IFERROR(N17/L17,"") -> 0.40286131
D18: =DATE(2025,1,1) -> 45658 | E18: =SUMIFS(tblAUM[AUM_CAD_Billions],tblAUM[Date],D18,tblAUM[Segment],"Asset Management") -> 359.858 | F18: =SUMIFS(tblAUM[AUM_CAD_Billions],tblAUM[Date],D18,tblAUM[Segment],"Wealth") -> 59.719 | G18: =SUMIFS(tblAUM[AUM_CAD_Billions],tblAUM[Date],D18,tblAUM[Segment],"Insurance") -> 29.591 | H18: =SUM(E18:G18) -> 449.168 | I18: =IFERROR(H18/H17-1,"") -> 0.0067329502 | K18: =D18 -> 45658 | L18: =SUMIFS(tblGL[Amount_CAD_Millions],tblGL[Date],K18,tblGL[Type],"Revenue") -> 147.591 | M18: =-SUMIFS(tblGL[Amount_CAD_Millions],tblGL[Date],K18,tblGL[Type],"Expense") -> 86.393 | N18: =L18-M18 -> 61.198 | O18: =IFERROR(N18/L18,"") -> 0.41464588
D19: =DATE(2025,2,1) -> 45689 | E19: =SUMIFS(tblAUM[AUM_CAD_Billions],tblAUM[Date],D19,tblAUM[Segment],"Asset Management") -> 360.677 | F19: =SUMIFS(tblAUM[AUM_CAD_Billions],tblAUM[Date],D19,tblAUM[Segment],"Wealth") -> 59.654 | G19: =SUMIFS(tblAUM[AUM_CAD_Billions],tblAUM[Date],D19,tblAUM[Segment],"Insurance") -> 29.969 | H19: =SUM(E19:G19) -> 450.3 | I19: =IFERROR(H19/H18-1,"") -> 0.0025202152 | K19: =D19 -> 45689 | L19: =SUMIFS(tblGL[Amount_CAD_Millions],tblGL[Date],K19,tblGL[Type],"Revenue") -> 154.327 | M19: =-SUMIFS(tblGL[Amount_CAD_Millions],tblGL[Date],K19,tblGL[Type],"Expense") -> 87.499 | N19: =L19-M19 -> 66.828 | O19: =IFERROR(N19/L19,"") -> 0.43302857
D20: =DATE(2025,3,1) -> 45717 | E20: =SUMIFS(tblAUM[AUM_CAD_Billions],tblAUM[Date],D20,tblAUM[Segment],"Asset Management") -> 360.454 | F20: =SUMIFS(tblAUM[AUM_CAD_Billions],tblAUM[Date],D20,tblAUM[Segment],"Wealth") -> 59.809 | G20: =SUMIFS(tblAUM[AUM_CAD_Billions],tblAUM[Date],D20,tblAUM[Segment],"Insurance") -> 30.065 | H20: =SUM(E20:G20) -> 450.328 | I20: =IFERROR(H20/H19-1,"") -> 6.2180768e-05 | K20: =D20 -> 45717 | L20: =SUMIFS(tblGL[Amount_CAD_Millions],tblGL[Date],K20,tblGL[Type],"Revenue") -> 148.293 | M20: =-SUMIFS(tblGL[Amount_CAD_Millions],tblGL[Date],K20,tblGL[Type],"Expense") -> 88.624 | N20: =L20-M20 -> 59.669 | O20: =IFERROR(N20/L20,"") -> 0.40237233
D21: =DATE(2025,4,1) -> 45748 | E21: =SUMIFS(tblAUM[AUM_CAD_Billions],tblAUM[Date],D21,tblAUM[Segment],"Asset Management") -> 364.904 | F21: =SUMIFS(tblAUM[AUM_CAD_Billions],tblAUM[Date],D21,tblAUM[Segment],"Wealth") -> 60.188 | G21: =SUMIFS(tblAUM[AUM_CAD_Billions],tblAUM[Date],D21,tblAUM[Segment],"Insurance") -> 30.025 | H21: =SUM(E21:G21) -> 455.117 | I21: =IFERROR(H21/H20-1,"") -> 0.010634471 | K21: =D21 -> 45748 | L21: =SUMIFS(tblGL[Amount_CAD_Millions],tblGL[Date],K21,tblGL[Type],"Revenue") -> 153.028 | M21: =-SUMIFS(tblGL[Amount_CAD_Millions],tblGL[Date],K21,tblGL[Type],"Expense") -> 90.82 | N21: =L21-M21 -> 62.208 | O21: =IFERROR(N21/L21,"") -> 0.40651384
D22: =DATE(2025,5,1) -> 45778 | E22: =SUMIFS(tblAUM[AUM_CAD_Billions],tblAUM[Date],D22,tblAUM[Segment],"Asset Management") -> 364.059 | F22: =SUMIFS(tblAUM[AUM_CAD_Billions],tblAUM[Date],D22,tblAUM[Segment],"Wealth") -> 60.338 | G22: =SUMIFS(tblAUM[AUM_CAD_Billions],tblAUM[Date],D22,tblAUM[Segment],"Insurance") -> 30.184 | H22: =SUM(E22:G22) -> 454.581 | I22: =IFERROR(H22/H21-1,"") -> -0.0011777191 | K22: =D22 -> 45778 | L22: =SUMIFS(tblGL[Amount_CAD_Millions],tblGL[Date],K22,tblGL[Type],"Revenue") -> 151.823 | M22: =-SUMIFS(tblGL[Amount_CAD_Millions],tblGL[Date],K22,tblGL[Type],"Expense") -> 88.483 | N22: =L22-M22 -> 63.34 | O22: =IFERROR(N22/L22,"") -> 0.41719634
D23: =DATE(2025,6,1) -> 45809 | E23: =SUMIFS(tblAUM[AUM_CAD_Billions],tblAUM[Date],D23,tblAUM[Segment],"Asset Management") -> 366.718 | F23: =SUMIFS(tblAUM[AUM_CAD_Billions],tblAUM[Date],D23,tblAUM[Segment],"Wealth") -> 60.65 | G23: =SUMIFS(tblAUM[AUM_CAD_Billions],tblAUM[Date],D23,tblAUM[Segment],"Insurance") -> 30.334 | H23: =SUM(E23:G23) -> 457.702 | I23: =IFERROR(H23/H22-1,"") -> 0.0068656631 | K23: =D23 -> 45809 | L23: =SUMIFS(tblGL[Amount_CAD_Millions],tblGL[Date],K23,tblGL[Type],"Revenue") -> 150.686 | M23: =-SUMIFS(tblGL[Amount_CAD_Millions],tblGL[Date],K23,tblGL[Type],"Expense") -> 90.535 | N23: =L23-M23 -> 60.151 | O23: =IFERROR(N23/L23,"") -> 0.39918108
D24: =DATE(2025,7,1) -> 45839 | E24: =SUMIFS(tblAUM[AUM_CAD_Billions],tblAUM[Date],D24,tblAUM[Segment],"Asset Management") -> 368.789 | F24: =SUMIFS(tblAUM[AUM_CAD_Billions],tblAUM[Date],D24,tblAUM[Segment],"Wealth") -> 61.09 | G24: =SUMIFS(tblAUM[AUM_CAD_Billions],tblAUM[Date],D24,tblAUM[Segment],"Insurance") -> 30.624 | H24: =SUM(E24:G24) -> 460.503 | I24: =IFERROR(H24/H23-1,"") -> 0.0061197023 | K24: =D24 -> 45839 | L24: =SUMIFS(tblGL[Amount_CAD_Millions],tblGL[Date],K24,tblGL[Type],"Revenue") -> 154.619 | M24: =-SUMIFS(tblGL[Amount_CAD_Millions],tblGL[Date],K24,tblGL[Type],"Expense") -> 87.67 | N24: =L24-M24 -> 66.949 | O24: =IFERROR(N24/L24,"") -> 0.43299336
D25: =DATE(2025,8,1) -> 45870 | E25: =SUMIFS(tblAUM[AUM_CAD_Billions],tblAUM[Date],D25,tblAUM[Segment],"Asset Management") -> 370.091 | F25: =SUMIFS(tblAUM[AUM_CAD_Billions],tblAUM[Date],D25,tblAUM[Segment],"Wealth") -> 61.038 | G25: =SUMIFS(tblAUM[AUM_CAD_Billions],tblAUM[Date],D25,tblAUM[Segment],"Insurance") -> 30.676 | H25: =SUM(E25:G25) -> 461.805 | I25: =IFERROR(H25/H24-1,"") -> 0.0028273431 | K25: =D25 -> 45870 | L25: =SUMIFS(tblGL[Amount_CAD_Millions],tblGL[Date],K25,tblGL[Type],"Revenue") -> 149.168 | M25: =-SUMIFS(tblGL[Amount_CAD_Millions],tblGL[Date],K25,tblGL[Type],"Expense") -> 90.283 | N25: =L25-M25 -> 58.885 | O25: =IFERROR(N25/L25,"") -> 0.39475625
D26: =DATE(2025,9,1) -> 45901 | E26: =SUMIFS(tblAUM[AUM_CAD_Billions],tblAUM[Date],D26,tblAUM[Segment],"Asset Management") -> 371.546 | F26: =SUMIFS(tblAUM[AUM_CAD_Billions],tblAUM[Date],D26,tblAUM[Segment],"Wealth") -> 57.341 | G26: =SUMIFS(tblAUM[AUM_CAD_Billions],tblAUM[Date],D26,tblAUM[Segment],"Insurance") -> 0 | H26: =SUM(E26:G26) -> 428.887 | I26: =IFERROR(H26/H25-1,"") -> -0.071281168 | K26: =D26 -> 45901 | L26: =SUMIFS(tblGL[Amount_CAD_Millions],tblGL[Date],K26,tblGL[Type],"Revenue") -> 155.429 | M26: =-SUMIFS(tblGL[Amount_CAD_Millions],tblGL[Date],K26,tblGL[Type],"Expense") -> 91.201 | N26: =L26-M26 -> 64.228 | O26: =IFERROR(N26/L26,"") -> 0.41323048

Sheet Controls
A1: MONTHLY CLOSE CONTROLS DASHBOARD
A2: ="Reporting Month: "&TEXT(Processed_Model!B2,"mmmm yyyy")&" | Prior: "&TEXT(Processed_Model!B3,"mmmm yyyy") -> Reporting Month: September 2025 | Prior: August 2025
A4: A. TIE-OUTS
A5: # | B5: Control | C5: Source A | D5: Source B | E5: Difference | F5: Tolerance | G5: Status
A6: 1 | B6: AUM Total (Current Month) vs Investments Total | C6: =SUMIFS(tblAUM[AUM_CAD_Billions],tblAUM[Date],Processed_Model!$B$2) -> 428.887 | D6: =SUMIFS(tblInvestments[Market_Value_CAD_Billions],tblInvestments[Date],Processed_Model!$B$2) -> 472.846 | E6: =C6-D6 -> -43.959 | F6: 0.5 | G6: =IF(ABS(E6)<=F6,"PASS","FAIL") -> FAIL
A7: 2 | B7: AUM Total (Prior Month) vs Investments Total | C7: =SUMIFS(tblAUM[AUM_CAD_Billions],tblAUM[Date],Processed_Model!$B$3) -> 461.805 | D7: =SUMIFS(tblInvestments[Market_Value_CAD_Billions],tblInvestments[Date],Processed_Model!$B$3) -> 423.499 | E7: =C7-D7 -> 38.306 | F7: 0.5 | G7: =IF(ABS(E7)<=F7,"PASS","FAIL") -> FAIL
A8: 3 | B8: GL Net Income (Current) is positive | C8: =SUMIFS(tblGL[Amount_CAD_Millions],tblGL[Date],Processed_Model!$B$2) -> 64.228 | D8: =0 -> 0 | E8: =C8-D8 -> 64.228 | F8: — | G8: =IF(C8>D8,"PASS","FAIL") -> PASS
A9: 4 | B9: Asset Mgmt AUM = Asset Mgmt Investments (Current) | C9: =SUMIFS(tblAUM[AUM_CAD_Billions],tblAUM[Date],Processed_Model!$B$2,tblAUM[Segment],"Asset Management") -> 371.546 | D9: =SUMIFS(tblInvestments[Market_Value_CAD_Billions],tblInvestments[Date],Processed_Model!$B$2,tblInvestments[Segment],"Asset Management") -> 404.001 | E9: =C9-D9 -> -32.455 | F9: 0.5 | G9: =IF(ABS(E9)<=F9,"PASS","FAIL") -> FAIL
A10: 5 | B10: Wealth AUM = Wealth Investments (Current) | C10: =SUMIFS(tblAUM[AUM_CAD_Billions],tblAUM[Date],Processed_Model!$B$2,tblAUM[Segment],"Wealth") -> 57.341 | D10: =SUMIFS(tblInvestments[Market_Value_CAD_Billions],tblInvestments[Date],Processed_Model!$B$2,tblInvestments[Segment],"Wealth") -> 68.845 | E10: =C10-D10 -> -11.504 | F10: 0.5 | G10: =IF(ABS(E10)<=F10,"PASS","FAIL") -> FAIL
A11: 6 | B11: Insurance AUM = Insurance Investments (Current) | C11: =SUMIFS(tblAUM[AUM_CAD_Billions],tblAUM[Date],Processed_Model!$B$2,tblAUM[Segment],"Insurance") -> 0 | D11: =SUMIFS(tblInvestments[Market_Value_CAD_Billions],tblInvestments[Date],Processed_Model!$B$2,tblInvestments[Segment],"Insurance") -> 0 | E11: =C11-D11 -> 0 | F11: 0.5 | G11: =IF(ABS(E11)<=F11,"PASS","FAIL") -> PASS
A12: 7 | B12: GL Revenue (Current) tied to GL by-segment rollup | C12: =SUMIFS(tblGL[Amount_CAD_Millions],tblGL[Date],Processed_Model!$B$2,tblGL[Type],"Revenue") -> 155.429 | D12: =SUM(Processed_Model!W3:W5) -> 155.429 | E12: =C12-D12 -> 0 | F12: 0.001 | G12: =IF(ABS(E12)<=F12,"PASS","FAIL") -> PASS
A13: 8 | B13: GL Expenses (Current) tied to GL by-segment rollup | C13: =-SUMIFS(tblGL[Amount_CAD_Millions],tblGL[Date],Processed_Model!$B$2,tblGL[Type],"Expense") -> 91.201 | D13: =SUM(Processed_Model!X3:X5) -> 91.201 | E13: =C13-D13 -> 0 | F13: 0.001 | G13: =IF(ABS(E13)<=F13,"PASS","FAIL") -> PASS
A14: 9 | B14: GL Net Income (Current) = Revenue – Expenses | C14: =SUMIFS(tblGL[Amount_CAD_Millions],tblGL[Date],Processed_Model!$B$2,tblGL[Type],"Revenue")+SUMIFS(tblGL[Amount_CAD_Millions],tblGL[Date],Processed_Model!$B$2,tblGL[Type],"Expense") -> 64.228 | D14: =SUM(Processed_Model!Y3:Y5) -> 64.228 | E14: =C14-D14 -> 0 | F14: 0.001 | G14: =IF(ABS(E14)<=F14,"PASS","FAIL") -> PASS
A16: B. VARIANCE CHECKS — Current vs Prior Month
A17: # | B17: Metric | C17: Current | D17: Prior | E17: Variance % | F17: Threshold | G17: Status
A18: 1 | B18: Total AUM | C18: =SUMIFS(tblAUM[AUM_CAD_Billions],tblAUM[Date],Processed_Model!$B$2) -> 428.887 | D18: =SUMIFS(tblAUM[AUM_CAD_Billions],tblAUM[Date],Processed_Model!$B$3) -> 461.805 | E18: =IFERROR((C18-D18)/D18,"") -> -0.071281168 | F18: =Processed_Model!$B$4 -> 0.05 | G18: =IF(OR(D18=0,C18=0),"INVESTIGATE",IF(ABS(E18)>F18,"FLAG","OK")) -> FLAG
A19: 2 | B19: Asset Management AUM | C19: =SUMIFS(tblAUM[AUM_CAD_Billions],tblAUM[Date],Processed_Model!$B$2,tblAUM[Segment],"Asset Management") -> 371.546 | D19: =SUMIFS(tblAUM[AUM_CAD_Billions],tblAUM[Date],Processed_Model!$B$3,tblAUM[Segment],"Asset Management") -> 370.091 | E19: =IFERROR((C19-D19)/D19,"") -> 0.0039314655 | F19: =Processed_Model!$B$4 -> 0.05 | G19: =IF(OR(D19=0,C19=0),"INVESTIGATE",IF(ABS(E19)>F19,"FLAG","OK")) -> OK
A20: 3 | B20: Wealth AUM | C20: =SUMIFS(tblAUM[AUM_CAD_Billions],tblAUM[Date],Processed_Model!$B$2,tblAUM[Segment],"Wealth") -> 57.341 | D20: =SUMIFS(tblAUM[AUM_CAD_Billions],tblAUM[Date],Processed_Model!$B$3,tblAUM[Segment],"Wealth") -> 61.038 | E20: =IFERROR((C20-D20)/D20,"") -> -0.060568826 | F20: =Processed_Model!$B$4 -> 0.05 | G20: =IF(OR(D20=0,C20=0),"INVESTIGATE",IF(ABS(E20)>F20,"FLAG","OK")) -> FLAG
A21: 4 | B21: Insurance AUM | C21: =SUMIFS(tblAUM[AUM_CAD_Billions],tblAUM[Date],Processed_Model!$B$2,tblAUM[Segment],"Insurance") -> 0 | D21: =SUMIFS(tblAUM[AUM_CAD_Billions],tblAUM[Date],Processed_Model!$B$3,tblAUM[Segment],"Insurance") -> 30.676 | E21: =IFERROR((C21-D21)/D21,"") -> -1 | F21: =Processed_Model!$B$4 -> 0.05 | G21: =IF(OR(D21=0,C21=0),"INVESTIGATE",IF(ABS(E21)>F21,"FLAG","OK")) -> INVESTIGATE
A22: 5 | B22: Total Revenue (GL) | C22: =SUMIFS(tblGL[Amount_CAD_Millions],tblGL[Date],Processed_Model!$B$2,tblGL[Type],"Revenue") -> 155.429 | D22: =SUMIFS(tblGL[Amount_CAD_Millions],tblGL[Date],Processed_Model!$B$3,tblGL[Type],"Revenue") -> 149.168 | E22: =IFERROR((C22-D22)/D22,"") -> 0.041972809 | F22: =Processed_Model!$B$4 -> 0.05 | G22: =IF(OR(D22=0,C22=0),"INVESTIGATE",IF(ABS(E22)>F22,"FLAG","OK")) -> OK
A23: 6 | B23: Total Expenses (GL) | C23: =-SUMIFS(tblGL[Amount_CAD_Millions],tblGL[Date],Processed_Model!$B$2,tblGL[Type],"Expense") -> 91.201 | D23: =-SUMIFS(tblGL[Amount_CAD_Millions],tblGL[Date],Processed_Model!$B$3,tblGL[Type],"Expense") -> 90.283 | E23: =IFERROR((C23-D23)/D23,"") -> 0.010168027 | F23: =Processed_Model!$B$4 -> 0.05 | G23: =IF(OR(D23=0,C23=0),"INVESTIGATE",IF(ABS(E23)>F23,"FLAG","OK")) -> OK
A25: C. DATA QUALITY CHECKS
A26: # | B26: Check | C26: Source Table | D26: Detail | E26: Count / Value | F26: Threshold | G26: Status
A27: 1 | B27: Missing AUM rows for current month | C27: tblAUM | D27: Expected 9 (segments × asset classes); count rows present | E27: =COUNTIFS(tblAUM[Date],Processed_Model!$B$2) -> 6 | F27: 9 | G27: =IF(E27<F27,"FAIL — MISSING DATA",IF(E27=F27,"PASS","INVESTIGATE")) -> FAIL — MISSING DATA
A28: 2 | B28: Missing GL rows for current month | C28: tblGL | D28: Expected 24 (segments × accounts); count rows present | E28: =COUNTIFS(tblGL[Date],Processed_Model!$B$2) -> 24 | F28: 24 | G28: =IF(E28<F28,"FAIL — MISSING DATA",IF(E28=F28,"PASS","INVESTIGATE")) -> PASS
A29: 3 | B29: Duplicate fund-month combos in Investments | C29: tblInvestments | D29: Same Fund + Date appearing >1 time | E29: {=SUMPRODUCT(((COUNTIFS(tblInvestments[Fund_Name],tblInvestments[Fund_Name],tblInvestments[Date],tblInvestments[Date])-1)/COUNTIFS(tblInvestments[Fund_Name],tblInvestments[Fund_Name],tblInvestments[Date],tblInvestments[Date]))*(COUNTIFS(tblInvestments[Fund_Name],tblInvestments[Fund_Name],tblInvestments[Date],tblInvestments[Date])>1))} -> 2 | F29: 0 | G29: =IF(E29<=F29,"PASS","FAIL — "&E29&" issue(s)") -> FAIL — 2 issue(s)
A30: 4 | B30: Outlier returns in current Investments | C30: tblInvestments | D30: ABS(Return%) > Outlier threshold | E30: {=SUMPRODUCT((ABS(tblInvestments[Return_Pct])>Processed_Model!$B$5)*(tblInvestments[Date]=Processed_Model!$B$2)*1)} -> 1 | F30: 0 | G30: =IF(E30<=F30,"PASS","FAIL — "&E30&" issue(s)") -> FAIL — 1 issue(s)
A31: 5 | B31: Negative AUM values | C31: tblAUM | D31: AUM should never be < 0 | E31: =COUNTIF(tblAUM[AUM_CAD_Billions],"<0") -> 0 | F31: 0 | G31: =IF(E31<=F31,"PASS","FAIL — "&E31&" issue(s)") -> PASS
A32: 6 | B32: Blank AUM values | C32: tblAUM | D32: Cells with no value in AUM column | E32: =COUNTBLANK(tblAUM[AUM_CAD_Billions]) -> 0 | F32: 0 | G32: =IF(E32<=F32,"PASS","FAIL — "&E32&" issue(s)") -> PASS
A33: 7 | B33: Distinct segments in AUM (expected 3) | C33: tblAUM | D33: Asset Management / Wealth / Insurance | E33: {=SUMPRODUCT(1/COUNTIF(tblAUM[Segment],tblAUM[Segment]))} -> 3 | F33: 3 | G33: =IF(E33=F33,"PASS","FAIL") -> PASS
A35: D. EXCEPTION REGISTER (auto-generated)
A36: Severity | B36: Category | C36: Issue | D36: Source / Reference | E36: Impact | F36: Owner | G36: Status
A37: HIGH | B37: Missing Data | C37: =IF(COUNTIFS(tblAUM[Date],Processed_Model!$B$2,tblAUM[Segment],"Insurance")=0,"Insurance segment AUM missing for current month","") -> Insurance segment AUM missing for current month | D37: Raw_AUM table — no Insurance rows for current period | E37: Total AUM understated; Insurance reporting blocked | F37: Finance Data Ops | G37: OPEN
A38: HIGH | B38: Variance | C38: =IF(ABS((SUMIFS(tblAUM[AUM_CAD_Billions],tblAUM[Date],Processed_Model!$B$2,tblAUM[Segment],"Wealth",tblAUM[Asset_Class],"Equities")-SUMIFS(tblAUM[AUM_CAD_Billions],tblAUM[Date],Processed_Model!$B$3,tblAUM[Segment],"Wealth",tblAUM[Asset_Class],"Equities"))/SUMIFS(tblAUM[AUM_CAD_Billions],tblAUM[Date],Processed_Model!$B$3,tblAUM[Segment],"Wealth",tblAUM[Asset_Class],"Equities"))>Processed_Model!$B$4,"Wealth/Equities AUM variance exceeds threshold","") -> Wealth/Equities AUM variance exceeds threshold | D38: Raw_AUM filtered to Wealth + Equities | E38: Possible market correction or data error — requires explanation | F38: Wealth Finance Lead | G38: OPEN
A39: MED | B39: Duplicates | C39: {=IF(SUMPRODUCT((COUNTIFS(tblInvestments[Fund_Name],tblInvestments[Fund_Name],tblInvestments[Date],tblInvestments[Date])>1)*1)>0,"Duplicate fund-period entries detected in Investments","")} -> Duplicate fund-period entries detected in Investments | D39: Raw_Investments — see DQ Check #3 | E39: Inflates Investment totals; breaks AUM↔Investments tie-out | F39: Finance Data Ops | G39: OPEN
A40: MED | B40: Outlier | C40: {=IF(SUMPRODUCT((ABS(tblInvestments[Return_Pct])>Processed_Model!$B$5)*(tblInvestments[Date]=Processed_Model!$B$2)*1)>0,"Outlier returns detected in current month Investments","")} -> Outlier returns detected in current month Investments | D40: Raw_Investments — see DQ Check #4 | E40: Possible data feed error or genuine event — confirm with Investment Ops | F40: Investment Ops | G40: OPEN

Sheet Variance_Detail
A1: AUM VARIANCE DETAIL — Current vs Prior Month
A2: ="Current: "&TEXT(Processed_Model!B2,"mmm-yyyy")&" | Prior: "&TEXT(Processed_Model!B3,"mmm-yyyy")&" | Threshold: "&TEXT(Processed_Model!B4,"0.0%") -> Current: Sep-2025 | Prior: Aug-2025 | Threshold: 5.0%
A4: Segment | B4: Asset Class | C4: Current ($B) | D4: Prior ($B) | E4: Δ ($B) | F4: Δ % | G4: Status
A5: Asset Management | B5: Fixed Income | C5: =SUMIFS(tblAUM[AUM_CAD_Billions],tblAUM[Date],Processed_Model!$B$2,tblAUM[Segment],A5,tblAUM[Asset_Class],B5) -> 237.262 | D5: =SUMIFS(tblAUM[AUM_CAD_Billions],tblAUM[Date],Processed_Model!$B$3,tblAUM[Segment],A5,tblAUM[Asset_Class],B5) -> 235.659 | E5: =C5-D5 -> 1.603 | F5: =IFERROR(E5/D5,"") -> 0.0068022015 | G5: =IF(OR(C5=0,D5=0),"INVESTIGATE",IF(ABS(F5)>Processed_Model!$B$4,"FLAG","OK")) -> OK
A6: Asset Management | B6: Equities | C6: =SUMIFS(tblAUM[AUM_CAD_Billions],tblAUM[Date],Processed_Model!$B$2,tblAUM[Segment],A6,tblAUM[Asset_Class],B6) -> 30.498 | D6: =SUMIFS(tblAUM[AUM_CAD_Billions],tblAUM[Date],Processed_Model!$B$3,tblAUM[Segment],A6,tblAUM[Asset_Class],B6) -> 30.521 | E6: =C6-D6 -> -0.023 | F6: =IFERROR(E6/D6,"") -> -0.0007535795 | G6: =IF(OR(C6=0,D6=0),"INVESTIGATE",IF(ABS(F6)>Processed_Model!$B$4,"FLAG","OK")) -> OK
A7: Asset Management | B7: Alternatives | C7: =SUMIFS(tblAUM[AUM_CAD_Billions],tblAUM[Date],Processed_Model!$B$2,tblAUM[Segment],A7,tblAUM[Asset_Class],B7) -> 103.786 | D7: =SUMIFS(tblAUM[AUM_CAD_Billions],tblAUM[Date],Processed_Model!$B$3,tblAUM[Segment],A7,tblAUM[Asset_Class],B7) -> 103.911 | E7: =C7-D7 -> -0.125 | F7: =IFERROR(E7/D7,"") -> -0.0012029525 | G7: =IF(OR(C7=0,D7=0),"INVESTIGATE",IF(ABS(F7)>Processed_Model!$B$4,"FLAG","OK")) -> OK
A8: Asset Management Total | C8: =SUM(C5:C7) -> 371.546 | D8: =SUM(D5:D7) -> 370.091 | E8: =C8-D8 -> 1.455 | F8: =IFERROR(E8/D8,"") -> 0.0039314655 | G8: =IF(OR(C8=0,D8=0),"INVESTIGATE",IF(ABS(F8)>Processed_Model!$B$4,"FLAG","OK")) -> OK
A9: Wealth | B9: Fixed Income | C9: =SUMIFS(tblAUM[AUM_CAD_Billions],tblAUM[Date],Processed_Model!$B$2,tblAUM[Segment],A9,tblAUM[Asset_Class],B9) -> 19.684 | D9: =SUMIFS(tblAUM[AUM_CAD_Billions],tblAUM[Date],Processed_Model!$B$3,tblAUM[Segment],A9,tblAUM[Asset_Class],B9) -> 19.675 | E9: =C9-D9 -> 0.009 | F9: =IFERROR(E9/D9,"") -> 0.00045743329 | G9: =IF(OR(C9=0,D9=0),"INVESTIGATE",IF(ABS(F9)>Processed_Model!$B$4,"FLAG","OK")) -> OK
A10: Wealth | B10: Equities | C10: =SUMIFS(tblAUM[AUM_CAD_Billions],tblAUM[Date],Processed_Model!$B$2,tblAUM[Segment],A10,tblAUM[Asset_Class],B10) -> 31.059 | D10: =SUMIFS(tblAUM[AUM_CAD_Billions],tblAUM[Date],Processed_Model!$B$3,tblAUM[Segment],A10,tblAUM[Asset_Class],B10) -> 34.798 | E10: =C10-D10 -> -3.739 | F10: =IFERROR(E10/D10,"") -> -0.1074487 | G10: =IF(OR(C10=0,D10=0),"INVESTIGATE",IF(ABS(F10)>Processed_Model!$B$4,"FLAG","OK")) -> FLAG
A11: Wealth | B11: Alternatives | C11: =SUMIFS(tblAUM[AUM_CAD_Billions],tblAUM[Date],Processed_Model!$B$2,tblAUM[Segment],A11,tblAUM[Asset_Class],B11) -> 6.598 | D11: =SUMIFS(tblAUM[AUM_CAD_Billions],tblAUM[Date],Processed_Model!$B$3,tblAUM[Segment],A11,tblAUM[Asset_Class],B11) -> 6.565 | E11: =C11-D11 -> 0.033 | F11: =IFERROR(E11/D11,"") -> 0.0050266565 | G11: =IF(OR(C11=0,D11=0),"INVESTIGATE",IF(ABS(F11)>Processed_Model!$B$4,"FLAG","OK")) -> OK
A12: Wealth Total | C12: =SUM(C9:C11) -> 57.341 | D12: =SUM(D9:D11) -> 61.038 | E12: =C12-D12 -> -3.697 | F12: =IFERROR(E12/D12,"") -> -0.060568826 | G12: =IF(OR(C12=0,D12=0),"INVESTIGATE",IF(ABS(F12)>Processed_Model!$B$4,"FLAG","OK")) -> FLAG
A13: Insurance | B13: Fixed Income | C13: =SUMIFS(tblAUM[AUM_CAD_Billions],tblAUM[Date],Processed_Model!$B$2,tblAUM[Segment],A13,tblAUM[Asset_Class],B13) -> 0 | D13: =SUMIFS(tblAUM[AUM_CAD_Billions],tblAUM[Date],Processed_Model!$B$3,tblAUM[Segment],A13,tblAUM[Asset_Class],B13) -> 24.14 | E13: =C13-D13 -> -24.14 | F13: =IFERROR(E13/D13,"") -> -1 | G13: =IF(OR(C13=0,D13=0),"INVESTIGATE",IF(ABS(F13)>Processed_Model!$B$4,"FLAG","OK")) -> INVESTIGATE
A14: Insurance | B14: Equities | C14: =SUMIFS(tblAUM[AUM_CAD_Billions],tblAUM[Date],Processed_Model!$B$2,tblAUM[Segment],A14,tblAUM[Asset_Class],B14) -> 0 | D14: =SUMIFS(tblAUM[AUM_CAD_Billions],tblAUM[Date],Processed_Model!$B$3,tblAUM[Segment],A14,tblAUM[Asset_Class],B14) -> 4.356 | E14: =C14-D14 -> -4.356 | F14: =IFERROR(E14/D14,"") -> -1 | G14: =IF(OR(C14=0,D14=0),"INVESTIGATE",IF(ABS(F14)>Processed_Model!$B$4,"FLAG","OK")) -> INVESTIGATE
A15: Insurance | B15: Alternatives | C15: =SUMIFS(tblAUM[AUM_CAD_Billions],tblAUM[Date],Processed_Model!$B$2,tblAUM[Segment],A15,tblAUM[Asset_Class],B15) -> 0 | D15: =SUMIFS(tblAUM[AUM_CAD_Billions],tblAUM[Date],Processed_Model!$B$3,tblAUM[Segment],A15,tblAUM[Asset_Class],B15) -> 2.18 | E15: =C15-D15 -> -2.18 | F15: =IFERROR(E15/D15,"") -> -1 | G15: =IF(OR(C15=0,D15=0),"INVESTIGATE",IF(ABS(F15)>Processed_Model!$B$4,"FLAG","OK")) -> INVESTIGATE
A16: Insurance Total | C16: =SUM(C13:C15) -> 0 | D16: =SUM(D13:D15) -> 30.676 | E16: =C16-D16 -> -30.676 | F16: =IFERROR(E16/D16,"") -> -1 | G16: =IF(OR(C16=0,D16=0),"INVESTIGATE",IF(ABS(F16)>Processed_Model!$B$4,"FLAG","OK")) -> INVESTIGATE
A17: GRAND TOTAL | C17: =SUMIFS(tblAUM[AUM_CAD_Billions],tblAUM[Date],Processed_Model!$B$2) -> 428.887 | D17: =SUMIFS(tblAUM[AUM_CAD_Billions],tblAUM[Date],Processed_Model!$B$3) -> 461.805 | E17: =C17-D17 -> -32.918 | F17: =IFERROR(E17/D17,"") -> -0.071281168 | G17: =IF(ABS(F17)>Processed_Model!$B$4,"FLAG","OK") -> FLAG
A19: GL VARIANCE — Revenue / Expenses by Segment
A20: Segment | B20: Metric | C20: Current ($M) | D20: Prior ($M) | E20: Δ ($M) | F20: Δ % | G20: Status
A21: Asset Management | B21: Revenue | C21: =SUMIFS(tblGL[Amount_CAD_Millions],tblGL[Date],Processed_Model!$B$2,tblGL[Segment],A21,tblGL[Type],"Revenue") -> 123 | D21: =SUMIFS(tblGL[Amount_CAD_Millions],tblGL[Date],Processed_Model!$B$3,tblGL[Segment],A21,tblGL[Type],"Revenue") -> 115.98 | E21: =C21-D21 -> 7.02 | F21: =IFERROR(E21/D21,"") -> 0.060527677 | G21: =IF(OR(C21=0,D21=0),"INVESTIGATE",IF(ABS(F21)>Processed_Model!$B$4,"FLAG","OK")) -> FLAG
A22: Asset Management | B22: Expenses | C22: =-SUMIFS(tblGL[Amount_CAD_Millions],tblGL[Date],Processed_Model!$B$2,tblGL[Segment],A22,tblGL[Type],"Expense") -> 64.731 | D22: =-SUMIFS(tblGL[Amount_CAD_Millions],tblGL[Date],Processed_Model!$B$3,tblGL[Segment],A22,tblGL[Type],"Expense") -> 64.09 | E22: =C22-D22 -> 0.641 | F22: =IFERROR(E22/D22,"") -> 0.01000156 | G22: =IF(OR(C22=0,D22=0),"INVESTIGATE",IF(ABS(F22)>Processed_Model!$B$4,"FLAG","OK")) -> OK
A23: Asset Management | B23: Net Income | C23: =SUMIFS(tblGL[Amount_CAD_Millions],tblGL[Date],Processed_Model!$B$2,tblGL[Segment],A23) -> 58.269 | D23: =SUMIFS(tblGL[Amount_CAD_Millions],tblGL[Date],Processed_Model!$B$3,tblGL[Segment],A23) -> 51.89 | E23: =C23-D23 -> 6.379 | F23: =IFERROR(E23/D23,"") -> 0.12293313 | G23: =IF(OR(C23=0,D23=0),"INVESTIGATE",IF(ABS(F23)>Processed_Model!$B$4,"FLAG","OK")) -> FLAG
A24: Wealth | B24: Revenue | C24: =SUMIFS(tblGL[Amount_CAD_Millions],tblGL[Date],Processed_Model!$B$2,tblGL[Segment],A24,tblGL[Type],"Revenue") -> 22.403 | D24: =SUMIFS(tblGL[Amount_CAD_Millions],tblGL[Date],Processed_Model!$B$3,tblGL[Segment],A24,tblGL[Type],"Revenue") -> 23.476 | E24: =C24-D24 -> -1.073 | F24: =IFERROR(E24/D24,"") -> -0.045706253 | G24: =IF(OR(C24=0,D24=0),"INVESTIGATE",IF(ABS(F24)>Processed_Model!$B$4,"FLAG","OK")) -> OK
A25: Wealth | B25: Expenses | C25: =-SUMIFS(tblGL[Amount_CAD_Millions],tblGL[Date],Processed_Model!$B$2,tblGL[Segment],A25,tblGL[Type],"Expense") -> 19.086 | D25: =-SUMIFS(tblGL[Amount_CAD_Millions],tblGL[Date],Processed_Model!$B$3,tblGL[Segment],A25,tblGL[Type],"Expense") -> 18.617 | E25: =C25-D25 -> 0.469 | F25: =IFERROR(E25/D25,"") -> 0.025192029 | G25: =IF(OR(C25=0,D25=0),"INVESTIGATE",IF(ABS(F25)>Processed_Model!$B$4,"FLAG","OK")) -> OK
A26: Wealth | B26: Net Income | C26: =SUMIFS(tblGL[Amount_CAD_Millions],tblGL[Date],Processed_Model!$B$2,tblGL[Segment],A26) -> 3.317 | D26: =SUMIFS(tblGL[Amount_CAD_Millions],tblGL[Date],Processed_Model!$B$3,tblGL[Segment],A26) -> 4.859 | E26: =C26-D26 -> -1.542 | F26: =IFERROR(E26/D26,"") -> -0.31734925 | G26: =IF(OR(C26=0,D26=0),"INVESTIGATE",IF(ABS(F26)>Processed_Model!$B$4,"FLAG","OK")) -> FLAG
A27: Insurance | B27: Revenue | C27: =SUMIFS(tblGL[Amount_CAD_Millions],tblGL[Date],Processed_Model!$B$2,tblGL[Segment],A27,tblGL[Type],"Revenue") -> 10.026 | D27: =SUMIFS(tblGL[Amount_CAD_Millions],tblGL[Date],Processed_Model!$B$3,tblGL[Segment],A27,tblGL[Type],"Revenue") -> 9.712 | E27: =C27-D27 -> 0.314 | F27: =IFERROR(E27/D27,"") -> 0.032331137 | G27: =IF(OR(C27=0,D27=0),"INVESTIGATE",IF(ABS(F27)>Processed_Model!$B$4,"FLAG","OK")) -> OK
A28: Insurance | B28: Expenses | C28: =-SUMIFS(tblGL[Amount_CAD_Millions],tblGL[Date],Processed_Model!$B$2,tblGL[Segment],A28,tblGL[Type],"Expense") -> 7.384 | D28: =-SUMIFS(tblGL[Amount_CAD_Millions],tblGL[Date],Processed_Model!$B$3,tblGL[Segment],A28,tblGL[Type],"Expense") -> 7.576 | E28: =C28-D28 -> -0.192 | F28: =IFERROR(E28/D28,"") -> -0.025343189 | G28: =IF(OR(C28=0,D28=0),"INVESTIGATE",IF(ABS(F28)>Processed_Model!$B$4,"FLAG","OK")) -> OK
A29: Insurance | B29: Net Income | C29: =SUMIFS(tblGL[Amount_CAD_Millions],tblGL[Date],Processed_Model!$B$2,tblGL[Segment],A29) -> 2.642 | D29: =SUMIFS(tblGL[Amount_CAD_Millions],tblGL[Date],Processed_Model!$B$3,tblGL[Segment],A29) -> 2.136 | E29: =C29-D29 -> 0.506 | F29: =IFERROR(E29/D29,"") -> 0.23689139 | G29: =IF(OR(C29=0,D29=0),"INVESTIGATE",IF(ABS(F29)>Processed_Model!$B$4,"FLAG","OK")) -> FLAG
